Workbook

Sheet mini_dashboard

Sheet products
A1: id | B1: item_type
A2: 2103 | B2: Cereal
A3: 7940 | B3: Household
A4: 2455 | B4: Clothes
A5: 1270 | B5: Beverages
A6: 8681 | B6: Office Supplies
A7: 4594 | B7: Fruits
A8: 5988 | B8: Vegetables
A9: 7331 | B9: Baby Food
A10: 8875 | B10: Meat
A11: 8293 | B11: Cosmetics
A12: 8969 | B12: Snacks
A13: 3127 | B13: Personal Care

Sheet countries
A1: name | B1: alpha-2 | C1: alpha-3 | D1: region | E1: sub-region
A2: Afghanistan | B2: AF | C2: AFG | D2: Asia | E2: Southern Asia
A3: Åland Islands | B3: AX | C3: ALA | D3: Europe | E3: Northern Europe
A4: Albania | B4: AL | C4: ALB | D4: Europe | E4: Southern Europe
A5: Algeria | B5: DZ | C5: DZA | D5: Africa | E5: Northern Africa
A6: American Samoa | B6: AS | C6: ASM | D6: Oceania | E6: Polynesia
A7: Andorra | B7: AD | C7: AND | D7: Europe | E7: Southern Europe
A8: Angola | B8: AO | C8: AGO | D8: Africa | E8: Sub-Saharan Africa
A9: Anguilla | B9: AI | C9: AIA | D9: Americas | E9: Latin America and the Caribbean
A10: Antarctica | B10: AQ | C10: ATA | D10: Antarctica | E10: Antarctica
A11: Antigua and Barbuda | B11: AG | C11: ATG | D11: Americas | E11: Latin America and the Caribbean
A12: Argentina | B12: AR | C12: ARG | D12: Americas | E12: Latin America and the Caribbean
... A250: Zimbabwe | B250: ZW | C250: ZWE | D250: Africa | E250: Sub-Saharan Africa

Sheet events
A1: Order ID | B1: Order Date | C1: mesOrder Date | D1: diaOrder Date | E1: anoOrder Date | F1: order date formatada | G1: Ship Date | H1: mesShip Date | I1: diaShip Date | J1: anoShip Date | K1: ship date formatada | L1: Order Priority | M1: Country Code | N1: Product ID | O1: Sales Channel | P1: Units Sold | Q1: Unit Price | R1: Unit Cost | S1: receita_total | T1: custo_total | U1: lucro_total | V1: item_type | W1: region | X1: sub-region | Y1: % margem | Z1: lead_time | AA1: dia da semana compra
A2: 100640618 | B2: 41861 | C2: =IFERROR(__xludf.DUMMYFUNCTION("split(B2,""/"")"),10.0) -> 10 | D2: =IFERROR(__xludf.DUMMYFUNCTION("""COMPUTED_VALUE"""),8.0) -> 8 | E2: =IFERROR(__xludf.DUMMYFUNCTION("""COMPUTED_VALUE"""),2014.0) -> 2014 | F2: =DATE(E2,C2,D2) -> 41920 | G2: 10/18/2014 | H2: =IFERROR(__xludf.DUMMYFUNCTION("split(G2,""/"")"),10.0) -> 10 | I2: =IFERROR(__xludf.DUMMYFUNCTION("""COMPUTED_VALUE"""),18.0) -> 18 | J2: =IFERROR(__xludf.DUMMYFUNCTION("""COMPUTED_VALUE"""),2014.0) -> 2014 | K2: =DATE(J2,H2,I2) -> 41930 | L2: M | M2: NOR | N2: 2103 | O2: Online | P2: 650 | Q2: 205.7 | R2: 117.11 | S2: =Q2*P2 -> 133705 | T2: =R2*P2 -> 76121.5 | U2: =S2-T2 -> 57583.5 | V2: =VLOOKUP(N2,products!A:B,2,0) -> Cereal | W2: Europe | X2: Northern Europe | Y2: =U2/S2 -> 0.43067574 | Z2: =K2-F2 -> 10 | AA2: =WEEKDAY(F2,1) -> 4 | AB2: margem total | AC2: =U1332/S1332 -> 0.29459244
A3: 100983083 | B3: 42682 | C3: =IFERROR(__xludf.DUMMYFUNCTION("split(B3,""/"")"),8.0) -> 8 | D3: =IFERROR(__xludf.DUMMYFUNCTION("""COMPUTED_VALUE"""),11.0) -> 11 | E3: =IFERROR(__xludf.DUMMYFUNCTION("""COMPUTED_VALUE"""),2016.0) -> 2016 | F3: =DATE(E3,C3,D3) -> 42593 | G3: 42682 | H3: =IFERROR(__xludf.DUMMYFUNCTION("split(G3,""/"")"),8.0) -> 8 | I3: =IFERROR(__xludf.DUMMYFUNCTION("""COMPUTED_VALUE"""),11.0) -> 11 | J3: =IFERROR(__xludf.DUMMYFUNCTION("""COMPUTED_VALUE"""),2016.0) -> 2016 | K3: =DATE(J3,H3,I3) -> 42593 | L3: C | M3: SRB | N3: 2103 | O3: Offline | P3: 1993 | Q3: 205.7 | R3: 117.11 | S3: =Q3*P3 -> 409960.1 | T3: =R3*P3 -> 233400.23 | U3: =S3-T3 -> 176559.87 | V3: =VLOOKUP(N3,products!A:B,2,0) -> Cereal | W3: Europe | X3: Southern Europe | Y3: =U3/S3 -> 0.43067574 | Z3: =K3-F3 -> 0 | AA3: =WEEKDAY(F3,1) -> 5 | AB3: margem media | AC3: =AVERAGE(Y2:Y1331) -> 0.34051759
A4: 101025998 | B4: 7/18/2014 | C4: =IFERROR(__xludf.DUMMYFUNCTION("split(B4,""/"")"),7.0) -> 7 | D4: =IFERROR(__xludf.DUMMYFUNCTION("""COMPUTED_VALUE"""),18.0) -> 18 | E4: =IFERROR(__xludf.DUMMYFUNCTION("""COMPUTED_VALUE"""),2014.0) -> 2014 | F4: =DATE(E4,C4,D4) -> 41838 | G4: 41951 | H4: =IFERROR(__xludf.DUMMYFUNCTION("split(G4,""/"")"),8.0) -> 8 | I4: =IFERROR(__xludf.DUMMYFUNCTION("""COMPUTED_VALUE"""),11.0) -> 11 | J4: =IFERROR(__xludf.DUMMYFUNCTION("""COMPUTED_VALUE"""),2014.0) -> 2014 | K4: =DATE(J4,H4,I4) -> 41862 | L4: M | M4: Desconhecido | N4: 7940 | O4: Online | P4: 4693 | Q4: 668.27 | R4: 502.54 | S4: =Q4*P4 -> 3136191.1 | T4: =R4*P4 -> 2358420.2 | U4: =S4-T4 -> 777770.89 | V4: =VLOOKUP(N4,products!A:B,2,0) -> Household | W4: Desconhecido | X4: Desconhecido | Y4: =U4/S4 -> 0.24799856 | Z4: =K4-F4 -> 24 | AA4: =WEEKDAY(F4,1) -> 6 | AB4: margem mediana | AC4: =MEDIAN(Y2:Y1331) -> 0.33003161
A5: 102230632 | B5: 5/13/2017 | C5: =IFERROR(__xludf.DUMMYFUNCTION("split(B5,""/"")"),5.0) -> 5 | D5: =IFERROR(__xludf.DUMMYFUNCTION("""COMPUTED_VALUE"""),13.0) -> 13 | E5: =IFERROR(__xludf.DUMMYFUNCTION("""COMPUTED_VALUE"""),2017.0) -> 2017 | F5: =DATE(E5,C5,D5) -> 42868 | G5: 6/13/2017 | H5: =IFERROR(__xludf.DUMMYFUNCTION("split(G5,""/"")"),6.0) -> 6 | I5: =IFERROR(__xludf.DUMMYFUNCTION("""COMPUTED_VALUE"""),13.0) -> 13 | J5: =IFERROR(__xludf.DUMMYFUNCTION("""COMPUTED_VALUE"""),2017.0) -> 2017 | K5: =DATE(J5,H5,I5) -> 42899 | L5: L | M5: MNE | N5: 2455 | O5: Online | P5: 1171 | Q5: 109.28 | R5: 35.84 | S5: =Q5*P5 -> 127966.88 | T5: =R5*P5 -> 41968.64 | U5: =S5-T5 -> 85998.24 | V5: =VLOOKUP(N5,products!A:B,2,0) -> Clothes | W5: Europe | X5: Southern Europe | Y5: =U5/S5 -> 0.67203514 | Z5: =K5-F5 -> 31 | AA5: =WEEKDAY(F5,1) -> 7
A6: 103435266 | B6: 41221 | C6: =IFERROR(__xludf.DUMMYFUNCTION("split(B6,""/"")"),8.0) -> 8 | D6: =IFERROR(__xludf.DUMMYFUNCTION("""COMPUTED_VALUE"""),11.0) -> 11 | E6: =IFERROR(__xludf.DUMMYFUNCTION("""COMPUTED_VALUE"""),2012.0) -> 2012 | F6: =DATE(E6,C6,D6) -> 41132 | G6: 9/18/2012 | H6: =IFERROR(__xludf.DUMMYFUNCTION("split(G6,""/"")"),9.0) -> 9 | I6: =IFERROR(__xludf.DUMMYFUNCTION("""COMPUTED_VALUE"""),18.0) -> 18 | J6: =IFERROR(__xludf.DUMMYFUNCTION("""COMPUTED_VALUE"""),2012.0) -> 2012 | K6: =DATE(J6,H6,I6) -> 41170 | L6: H | M6: SRB | N6: 1270 | O6: Offline | P6: 7648 | Q6: 47.45 | R6: 31.79 | S6: =Q6*P6 -> 362897.6 | T6: =R6*P6 -> 243129.92 | U6: =S6-T6 -> 119767.68 | V6: =VLOOKUP(N6,products!A:B,2,0) -> Beverages | W6: Europe | X6: Southern Europe | Y6: =U6/S6 -> 0.33003161 | Z6: =K6-F6 -> 38 | AA6: =WEEKDAY(F6,1) -> 7
A7: 103450715 | B7: 3/15/2015 | C7: =IFERROR(__xludf.DUMMYFUNCTION("split(B7,""/"")"),3.0) -> 3 | D7: =IFERROR(__xludf.DUMMYFUNCTION("""COMPUTED_VALUE"""),15.0) -> 15 | E7: =IFERROR(__xludf.DUMMYFUNCTION("""COMPUTED_VALUE"""),2015.0) -> 2015 | F7: =DATE(E7,C7,D7) -> 42078 | G7: 4/18/2015 | H7: =IFERROR(__xludf.DUMMYFUNCTION("split(G7,""/"")"),4.0) -> 4 | I7: =IFERROR(__xludf.DUMMYFUNCTION("""COMPUTED_VALUE"""),18.0) -> 18 | J7: =IFERROR(__xludf.DUMMYFUNCTION("""COMPUTED_VALUE"""),2015.0) -> 2015 | K7: =DATE(J7,H7,I7) -> 42112 | L7: H | M7: SVK | N7: 8681 | O7: Online | P7: 2220 | Q7: 651.21 | R7: 524.96 | S7: =Q7*P7 -> 1445686.2 | T7: =R7*P7 -> 1165411.2 | U7: =S7-T7 -> 280275 | V7: =VLOOKUP(N7,products!A:B,2,0) -> Office Supplies | W7: Europe | X7: Eastern Europe | Y7: =U7/S7 -> 0.19386987 | Z7: =K7-F7 -> 34 | AA7: =WEEKDAY(F7,1) -> 1
A8: 103499639 | B8: 4/20/2013 | C8: =IFERROR(__xludf.DUMMYFUNCTION("split(B8,""/"")"),4.0) -> 4 | D8: =IFERROR(__xludf.DUMMYFUNCTION("""COMPUTED_VALUE"""),20.0) -> 20 | E8: =IFERROR(__xludf.DUMMYFUNCTION("""COMPUTED_VALUE"""),2013.0) -> 2013 | F8: =DATE(E8,C8,D8) -> 41384 | G8: 41431 | H8: =IFERROR(__xludf.DUMMYFUNCTION("split(G8,""/"")"),6.0) -> 6 | I8: =IFERROR(__xludf.DUMMYFUNCTION("""COMPUTED_VALUE"""),6.0) -> 6 | J8: =IFERROR(__xludf.DUMMYFUNCTION("""COMPUTED_VALUE"""),2013.0) -> 2013 | K8: =DATE(J8,H8,I8) -> 41431 | L8: L | M8: FRA | N8: 4594 | O8: Online | P8: 6698 | Q8: 9.33 | R8: 6.92 | S8: =Q8*P8 -> 62492.34 | T8: =R8*P8 -> 46350.16 | U8: =S8-T8 -> 16142.18 | V8: =VLOOKUP(N8,products!A:B,2,0) -> Fruits | W8: Europe | X8: Western Europe | Y8: =U8/S8 -> 0.25830654 | Z8: =K8-F8 -> 47 | AA8: =WEEKDAY(F8,1) -> 7
A9: 103762280 | B9: 40888 | C9: =IFERROR(__xludf.DUMMYFUNCTION("split(B9,""/"")"),11.0) -> 11 | D9: =IFERROR(__xludf.DUMMYFUNCTION("""COMPUTED_VALUE"""),12.0) -> 12 | E9: =IFERROR(__xludf.DUMMYFUNCTION("""COMPUTED_VALUE"""),2011.0) -> 2011 | F9: =DATE(E9,C9,D9) -> 40859 | G9: 12/14/2011 | H9: =IFERROR(__xludf.DUMMYFUNCTION("split(G9,""/"")"),12.0) -> 12 | I9: =IFERROR(__xludf.DUMMYFUNCTION("""COMPUTED_VALUE"""),14.0) -> 14 | J9: =IFERROR(__xludf.DUMMYFUNCTION("""COMPUTED_VALUE"""),2011.0) -> 2011 | K9: =DATE(J9,H9,I9) -> 40891 | L9: M | M9: ESP | N9: 5988 | O9: Online | P9: 4419 | Q9: 154.06 | R9: 90.93 | S9: =Q9*P9 -> 680791.14 | T9: =R9*P9 -> 401819.67 | U9: =S9-T9 -> 278971.47 | V9: =VLOOKUP(N9,products!A:B,2,0) -> Vegetables | W9: Europe | X9: Southern Europe | Y9: =U9/S9 -> 0.40977541 | Z9: =K9-F9 -> 32 | AA9: =WEEKDAY(F9,1) -> 7
A10: 103832662 | B10: 9/19/2012 | C10: =IFERROR(__xludf.DUMMYFUNCTION("split(B10,""/"")"),9.0) -> 9 | D10: =IFERROR(__xludf.DUMMYFUNCTION("""COMPUTED_VALUE"""),19.0) -> 19 | E10: =IFERROR(__xludf.DUMMYFUNCTION("""COMPUTED_VALUE"""),2012.0) -> 2012 | F10: =DATE(E10,C10,D10) -> 41171 | G10: 10/20/2012 | H10: =IFERROR(__xludf.DUMMYFUNCTION("split(G10,""/"")"),10.0) -> 10 | I10: =IFERROR(__xludf.DUMMYFUNCTION("""COMPUTED_VALUE"""),20.0) -> 20 | J10: =IFERROR(__xludf.DUMMYFUNCTION("""COMPUTED_VALUE"""),2012.0) -> 2012 | K10: =DATE(J10,H10,I10) -> 41202 | L10: H | M10: HRV | N10: 7331 | O10: Offline | P10: 5247 | Q10: 255.28 | R10: 159.42 | S10: =Q10*P10 -> 1339454.2 | T10: =R10*P10 -> 836476.74 | U10: =S10-T10 -> 502977.42 | V10: =VLOOKUP(N10,products!A:B,2,0) -> Baby Food | W10: Europe | X10: Southern Europe | Y10: =U10/S10 -> 0.37550924 | Z10: =K10-F10 -> 31 | AA10: =WEEKDAY(F10,1) -> 4
A11: 104008615 | B11: 1/23/2011 | C11: =IFERROR(__xludf.DUMMYFUNCTION("split(B11,""/"")"),1.0) -> 1 | D11: =IFERROR(__xludf.DUMMYFUNCTION("""COMPUTED_VALUE"""),23.0) -> 23 | E11: =IFERROR(__xludf.DUMMYFUNCTION("""COMPUTED_VALUE"""),2011.0) -> 2011 | F11: =DATE(E11,C11,D11) -> 40566 | G11: 2/22/2011 | H11: =IFERROR(__xludf.DUMMYFUNCTION("split(G11,""/"")"),2.0) -> 2 | I11: =IFERROR(__xludf.DUMMYFUNCTION("""COMPUTED_VALUE"""),22.0) -> 22 | J11: =IFERROR(__xludf.DUMMYFUNCTION("""COMPUTED_VALUE"""),2011.0) -> 2011 | K11: =DATE(J11,H11,I11) -> 40596 | L11: M | M11: DEU | N11: 2103 | O11: Online | P11: 7315 | Q11: 205.7 | R11: 117.11 | S11: =Q11*P11 -> 1504695.5 | T11: =R11*P11 -> 856659.65 | U11: =S11-T11 -> 648035.85 | V11: =VLOOKUP(N11,products!A:B,2,0) -> Cereal | W11: Europe | X11: Western Europe | Y11: =U11/S11 -> 0.43067574 | Z11: =K11-F11 -> 30 | AA11: =WEEKDAY(F11,1) -> 1
A12: 104165685 | B12: 2/19/2012 | C12: =IFERROR(__xludf.DUMMYFUNCTION("split(B12,""/"")"),2.0) -> 2 | D12: =IFERROR(__xludf.DUMMYFUNCTION("""COMPUTED_VALUE"""),19.0) -> 19 | E12: =IFERROR(__xludf.DUMMYFUNCTION("""COMPUTED_VALUE"""),2012.0) -> 2012 | F12: =DATE(E12,C12,D12) -> 40958 | G12: 41063 | H12: =IFERROR(__xludf.DUMMYFUNCTION("split(G12,""/"")"),3.0) -> 3 | I12: =IFERROR(__xludf.DUMMYFUNCTION("""COMPUTED_VALUE"""),6.0) -> 6 | J12: =IFERROR(__xludf.DUMMYFUNCTION("""COMPUTED_VALUE"""),2012.0) -> 2012 | K12: =DATE(J12,H12,I12) -> 40974 | L12: L | M12: ARM | N12: 7940 | O12: Online | P12: 3796 | Q12: 668.27 | R12: 502.54 | S12: =Q12*P12 -> 2536752.9 | T12: =R12*P12 -> 1907641.8 | U12: =S12-T12 -> 629111.08 | V12: =VLOOKUP(N12,products!A:B,2,0) -> Household | W12: Asia | X12: Western Asia | Y12: =U12/S12 -> 0.24799856 | Z12: =K12-F12 -> 16 | AA12: =WEEKDAY(F12,1) -> 1
A13: 104190576 | B13: 2/22/2017 | C13: =IFERROR(__xludf.DUMMYFUNCTION("split(B13,""/"")"),2.0) -> 2 | D13: =IFERROR(__xludf.DUMMYFUNCTION("""COMPUTED_VALUE"""),22.0) -> 22 | E13: =IFERROR(__xludf.DUMMYFUNCTION("""COMPUTED_VALUE"""),2017.0) -> 2017 | F13: =DATE(E13,C13,D13) -> 42788 | G13: 43072 | H13: =IFERROR(__xludf.DUMMYFUNCTION("split(G13,""/"")"),3.0) -> 3 | I13: =IFERROR(__xludf.DUMMYFUNCTION("""COMPUTED_VALUE"""),12.0) -> 12 | J13: =IFERROR(__xludf.DUMMYFUNCTION("""COMPUTED_VALUE"""),2017.0) -> 2017 | K13: =DATE(J13,H13,I13) -> 42806 | L13: C | M13: GEO | N13: 8875 | O13: Offline | P13: 1162 | Q13: 421.89 | R13: 364.69 | S13: =Q13*P13 -> 490236.18 | T13: =R13*P13 -> 423769.78 | U13: =S13-T13 -> 66466.4 | V13: =VLOOKUP(N13,products!A:B,2,0) -> Meat | W13: Asia | X13: Western Asia | Y13: =U13/S13 -> 0.13558036 | Z13: =K13-F13 -> 18 | AA13: =WEEKDAY(F13,1) -> 4
A14: 104245078 | B14: 3/27/2013 | C14: =IFERROR(__xludf.DUMMYFUNCTION("split(B14,""/"")"),3.0) -> 3 | D14: =IFERROR(__xludf.DUMMYFUNCTION("""COMPUTED_VALUE"""),27.0) -> 27 | E14: =IFERROR(__xludf.DUMMYFUNCTION("""COMPUTED_VALUE"""),2013.0) -> 2013 | F14: =DATE(E14,C14,D14) -> 41360 | G14: 4/21/2013 | H14: =IFERROR(__xludf.DUMMYFUNCTION("split(G14,""/"")"),4.0) -> 4 | I14: =IFERROR(__xludf.DUMMYFUNCTION("""COMPUTED_VALUE"""),21.0) -> 21 | J14: =IFERROR(__xludf.DUMMYFUNCTION("""COMPUTED_VALUE"""),2013.0) -> 2013 | K14: =DATE(J14,H14,I14) -> 41385 | L14: M | M14: GBR | N14: 4594 | O14: Offline | P14: 7290 | Q14: 9.33 | R14: 6.92 | S14: =Q14*P14 -> 68015.7 | T14: =R14*P14 -> 50446.8 | U14: =S14-T14 -> 17568.9 | V14: =VLOOKUP(N14,products!A:B,2,0) -> Fruits | W14: Europe | X14: Northern Europe | Y14: =U14/S14 -> 0.25830654 | Z14: =K14-F14 -> 25 | AA14: =WEEKDAY(F14,1) -> 4
A15: 104548490 | B15: 41640 | C15: =IFERROR(__xludf.DUMMYFUNCTION("split(B15,""/"")"),1.0) -> 1 | D15: =IFERROR(__xludf.DUMMYFUNCTION("""COMPUTED_VALUE"""),1.0) -> 1 | E15: =IFERROR(__xludf.DUMMYFUNCTION("""COMPUTED_VALUE"""),2014.0) -> 2014 | F15: =DATE(E15,C15,D15) -> 41640 | G15: 41760 | H15: =IFERROR(__xludf.DUMMYFUNCTION("split(G15,""/"")"),1.0) -> 1 | I15: =IFERROR(__xludf.DUMMYFUNCTION("""COMPUTED_VALUE"""),5.0) -> 5 | J15: =IFERROR(__xludf.DUMMYFUNCTION("""COMPUTED_VALUE"""),2014.0) -> 2014 | K15: =DATE(J15,H15,I15) -> 41644 | L15: M | M15: Desconhecido | N15: 7331 | O15: Online | P15: 7076 | Q15: 255.28 | R15: 159.42 | S15: =Q15*P15 -> 1806361.3 | T15: =R15*P15 -> 1128055.9 | U15: =S15-T15 -> 678305.36 | V15: =VLOOKUP(N15,products!A:B,2,0) -> Baby Food | W15: Desconhecido | X15: Desconhecido | Y15: =U15/S15 -> 0.37550924 | Z15: =K15-F15 -> 4 | AA15: =WEEKDAY(F15,1) -> 4
A16: 105030000 | B16: 42406 | C16: =IFERROR(__xludf.DUMMYFUNCTION("split(B16,""/"")"),6.0) -> 6 | D16: =IFERROR(__xludf.DUMMYFUNCTION("""COMPUTED_VALUE"""),2.0) -> 2 | E16: =IFERROR(__xludf.DUMMYFUNCTION("""COMPUTED_VALUE"""),2016.0) -> 2016 | F16: =DATE(E16,C16,D16) -> 42523 | G16: 6/13/2016 | H16: =IFERROR(__xludf.DUMMYFUNCTION("split(G16,""/"")"),6.0) -> 6 | I16: =IFERROR(__xludf.DUMMYFUNCTION("""COMPUTED_VALUE"""),13.0) -> 13 | J16: =IFERROR(__xludf.DUMMYFUNCTION("""COMPUTED_VALUE"""),2016.0) -> 2016 | K16: =DATE(J16,H16,I16) -> 42534 | L16: C | M16: SVN | N16: 2455 | O16: Offline | P16: 9566 | Q16: 109.28 | R16: 35.84 | S16: =Q16*P16 -> 1045372.5 | T16: =R16*P16 -> 342845.44 | U16: =S16-T16 -> 702527.04 | V16: =VLOOKUP(N16,products!A:B,2,0) -> Clothes | W16: Europe | X16: Southern Europe | Y16: =U16/S16 -> 0.67203514 | Z16: =K16-F16 -> 11 | AA16: =WEEKDAY(F16,1) -> 5
A17: 107651269 | B17: 10/28/2013 | C17: =IFERROR(__xludf.DUMMYFUNCTION("split(B17,""/"")"),10.0) -> 10 | D17: =IFERROR(__xludf.DUMMYFUNCTION("""COMPUTED_VALUE"""),28.0) -> 28 | E17: =IFERROR(__xludf.DUMMYFUNCTION("""COMPUTED_VALUE"""),2013.0) -> 2013 | F17: =DATE(E17,C17,D17) -> 41575 | G17: 41589 | H17: =IFERROR(__xludf.DUMMYFUNCTION("split(G17,""/"")"),11.0) -> 11 | I17: =IFERROR(__xludf.DUMMYFUNCTION("""COMPUTED_VALUE"""),11.0) -> 11 | J17: =IFERROR(__xludf.DUMMYFUNCTION("""COMPUTED_VALUE"""),2013.0) -> 2013 | K17: =DATE(J17,H17,I17) -> 41589 | L17: M | M17: HRV | N17: 7940 | O17: Online | P17: 5258 | Q17: 668.27 | R17: 502.54 | S17: =Q17*P17 -> 3513763.7 | T17: =R17*P17 -> 2642355.3 | U17: =S17-T17 -> 871408.34 | V17: =VLOOKUP(N17,products!A:B,2,0) -> Household | W17: Europe | X17: Southern Europe | Y17: =U17/S17 -> 0.24799856 | Z17: =K17-F17 -> 14 | AA17: =WEEKDAY(F17,1) -> 2
A18: 108407437 | B18: 2/19/2015 | C18: =IFERROR(__xludf.DUMMYFUNCTION("split(B18,""/"")"),2.0) -> 2 | D18: =IFERROR(__xludf.DUMMYFUNCTION("""COMPUTED_VALUE"""),19.0) -> 19 | E18: =IFERROR(__xludf.DUMMYFUNCTION("""COMPUTED_VALUE"""),2015.0) -> 2015 | F18: =DATE(E18,C18,D18) -> 42054 | G18: 3/27/2015 | H18: =IFERROR(__xludf.DUMMYFUNCTION("split(G18,""/"")"),3.0) -> 3 | I18: =IFERROR(__xludf.DUMMYFUNCTION("""COMPUTED_VALUE"""),27.0) -> 27 | J18: =IFERROR(__xludf.DUMMYFUNCTION("""COMPUTED_VALUE"""),2015.0) -> 2015 | K18: =DATE(J18,H18,I18) -> 42090 | L18: C | M18: ROU | N18: 7331 | O18: Offline | P18: 9025 | Q18: 255.28 | R18: 159.42 | S18: =Q18*P18 -> 2303902 | T18: =R18*P18 -> 1438765.5 | U18: =S18-T18 -> 865136.5 | V18: =VLOOKUP(N18,products!A:B,2,0) -> Baby Food | W18: Europe | X18: Eastern Europe | Y18: =U18/S18 -> 0.37550924 | Z18: =K18-F18 -> 36 | AA18: =WEEKDAY(F18,1) -> 5
A19: 109914195 | B19: 41246 | C19: =IFERROR(__xludf.DUMMYFUNCTION("split(B19,""/"")"),3.0) -> 3 | D19: =IFERROR(__xludf.DUMMYFUNCTION("""COMPUTED_VALUE"""),12.0) -> 12 | E19: =IFERROR(__xludf.DUMMYFUNCTION("""COMPUTED_VALUE"""),2012.0) -> 2012 | F19: =DATE(E19,C19,D19) -> 40980 | G19: 4/16/2012 | H19: =IFERROR(__xludf.DUMMYFUNCTION("split(G19,""/"")"),4.0) -> 4 | I19: =IFERROR(__xludf.DUMMYFUNCTION("""COMPUTED_VALUE"""),16.0) -> 16 | J19: =IFERROR(__xludf.DUMMYFUNCTION("""COMPUTED_VALUE"""),2012.0) -> 2012 | K19: =DATE(J19,H19,I19) -> 41015 | L19: M | M19: POL | N19: 2455 | O19: Offline | P19: 4908 | Q19: 109.28 | R19: 35.84 | S19: =Q19*P19 -> 536346.24 | T19: =R19*P19 -> 175902.72 | U19: =S19-T19 -> 360443.52 | V19: =VLOOKUP(N19,products!A:B,2,0) -> Clothes | W19: Europe | X19: Eastern Europe | Y19: =U19/S19 -> 0.67203514 | Z19: =K19-F19 -> 35 | AA19: =WEEKDAY(F19,1) -> 2
A20: 111063039 | B20: 5/26/2012 | C20: =IFERROR(__xludf.DUMMYFUNCTION("split(B20,""/"")"),5.0) -> 5 | D20: =IFERROR(__xludf.DUMMYFUNCTION("""COMPUTED_VALUE"""),26.0) -> 26 | E20: =IFERROR(__xludf.DUMMYFUNCTION("""COMPUTED_VALUE"""),2012.0) -> 2012 | F20: =DATE(E20,C20,D20) -> 41055 | G20: 7/13/2012 | H20: =IFERROR(__xludf.DUMMYFUNCTION("split(G20,""/"")"),7.0) -> 7 | I20: =IFERROR(__xludf.DUMMYFUNCTION("""COMPUTED_VALUE"""),13.0) -> 13 | J20: =IFERROR(__xludf.DUMMYFUNCTION("""COMPUTED_VALUE"""),2012.0) -> 2012 | K20: =DATE(J20,H20,I20) -> 41103 | L20: L | M20: LUX | N20: 7331 | O20: Online | P20: 4876 | Q20: 255.28 | R20: 159.42 | S20: =Q20*P20 -> 1244745.3 | T20: =R20*P20 -> 777331.92 | U20: =S20-T20 -> 467413.36 | V20: =VLOOKUP(N20,products!A:B,2,0) -> Baby Food | W20: Europe | X20: Western Europe | Y20: =U20/S20 -> 0.37550924 | Z20: =K20-F20 -> 48 | AA20: =WEEKDAY(F20,1) -> 7
A21: 111246287 | B21: 42984 | C21: =IFERROR(__xludf.DUMMYFUNCTION("split(B21,""/"")"),6.0) -> 6 | D21: =IFERROR(__xludf.DUMMYFUNCTION("""COMPUTED_VALUE"""),9.0) -> 9 | E21: =IFERROR(__xludf.DUMMYFUNCTION("""COMPUTED_VALUE"""),2017.0) -> 2017 | F21: =DATE(E21,C21,D21) -> 42895 | G21: 42773 | H21: =IFERROR(__xludf.DUMMYFUNCTION("split(G21,""/"")"),7.0) -> 7 | I21: =IFERROR(__xludf.DUMMYFUNCTION("""COMPUTED_VALUE"""),2.0) -> 2 | J21: =IFERROR(__xludf.DUMMYFUNCTION("""COMPUTED_VALUE"""),2017.0) -> 2017 | K21: =DATE(J21,H21,I21) -> 42918 | L21: M | M21: CYP | N21: 8875 | O21: Offline | P21: 9103 | Q21: 421.89 | R21: 364.69 | S21: =Q21*P21 -> 3840464.7 | T21: =R21*P21 -> 3319773.1 | U21: =S21-T21 -> 520691.6 | V21: =VLOOKUP(N21,products!A:B,2,0) -> Meat | W21: Asia | X21: Western Asia | Y21: =U21/S21 -> 0.13558036 | Z21: =K21-F21 -> 23 | AA21: =WEEKDAY(F21,1) -> 6
A22: 111496055 | B22: 4/28/2011 | C22: =IFERROR(__xludf.DUMMYFUNCTION("split(B22,""/"")"),4.0) -> 4 | D22: =IFERROR(__xludf.DUMMYFUNCTION("""COMPUTED_VALUE"""),28.0) -> 28 | E22: =IFERROR(__xludf.DUMMYFUNCTION("""COMPUTED_VALUE"""),2011.0) -> 2011 | F22: =DATE(E22,C22,D22) -> 40661 | G22: 40639 | H22: =IFERROR(__xludf.DUMMYFUNCTION("split(G22,""/"")"),6.0) -> 6 | I22: =IFERROR(__xludf.DUMMYFUNCTION("""COMPUTED_VALUE"""),4.0) -> 4 | J22: =IFERROR(__xludf.DUMMYFUNCTION("""COMPUTED_VALUE"""),2011.0) -> 2011 | K22: =DATE(J22,H22,I22) -> 40698 | L22: M | M22: BEL | N22: 4594 | O22: Online | P22: 3015 | Q22: 9.33 | R22: 6.92 | S22: =Q22*P22 -> 28129.95 | T22: =R22*P22 -> 20863.8 | U22: =S22-T22 -> 7266.15 | V22: =VLOOKUP(N22,products!A:B,2,0) -> Fruits | W22: Europe | X22: Western Europe | Y22: =U22/S22 -> 0.25830654 | Z22: =K22-F22 -> 37 | AA22: =WEEKDAY(F22,1) -> 5
A23: 111893022 | B23: 10/28/2016 | C23: =IFERROR(__xludf.DUMMYFUNCTION("split(B23,""/"")"),10.0) -> 10 | D23: =IFERROR(__xludf.DUMMYFUNCTION("""COMPUTED_VALUE"""),28.0) -> 28 | E23: =IFERROR(__xludf.DUMMYFUNCTION("""COMPUTED_VALUE"""),2016.0) -> 2016 | F23: =DATE(E23,C23,D23) -> 42671 | G23: 42412 | H23: =IFERROR(__xludf.DUMMYFUNCTION("split(G23,""/"")"),12.0) -> 12 | I23: =IFERROR(__xludf.DUMMYFUNCTION("""COMPUTED_VALUE"""),2.0) -> 2 | J23: =IFERROR(__xludf.DUMMYFUNCTION("""COMPUTED_VALUE"""),2016.0) -> 2016 | K23: =DATE(J23,H23,I23) -> 42706 | L23: L | M23: SVN | N23: 7331 | O23: Online | P23: 486 | Q23: 255.28 | R23: 159.42 | S23: =Q23*P23 -> 124066.08 | T23: =R23*P23 -> 77478.12 | U23: =S23-T23 -> 46587.96 | V23: =VLOOKUP(N23,products!A:B,2,0) -> Baby Food | W23: Europe | X23: Southern Europe | Y23: =U23/S23 -> 0.37550924 | Z23: =K23-F23 -> 35 | AA23: =WEEKDAY(F23,1) -> 6
A24: 112330758 | B24: 12/15/2016 | C24: =IFERROR(__xludf.DUMMYFUNCTION("split(B24,""/"")"),12.0) -> 12 | D24: =IFERROR(__xludf.DUMMYFUNCTION("""COMPUTED_VALUE"""),15.0) -> 15 | E24: =IFERROR(__xludf.DUMMYFUNCTION("""COMPUTED_VALUE"""),2016.0) -> 2016 | F24: =DATE(E24,C24,D24) -> 42719 | G24: 43040 | H24: =IFERROR(__xludf.DUMMYFUNCTION("split(G24,""/"")"),1.0) -> 1 | I24: =IFERROR(__xludf.DUMMYFUNCTION("""COMPUTED_VALUE"""),11.0) -> 11 | J24: =IFERROR(__xludf.DUMMYFUNCTION("""COMPUTED_VALUE"""),2017.0) -> 2017 | K24: =DATE(J24,H24,I24) -> 42746 | L24: C | M24: LTU | N24: 8681 | O24: Offline | P24: 22 | Q24: 651.21 | R24: 524.96 | S24: =Q24*P24 -> 14326.62 | T24: =R24*P24 -> 11549.12 | U24: =S24-T24 -> 2777.5 | V24: =VLOOKUP(N24,products!A:B,2,0) -> Office Supplies | W24: Europe | X24: Northern Europe | Y24: =U24/S24 -> 0.19386987 | Z24: =K24-F24 -> 27 | AA24: =WEEKDAY(F24,1) -> 5
A25: 113524663 | B25: 10/29/2010 | C25: =IFERROR(__xludf.DUMMYFUNCTION("split(B25,""/"")"),10.0) -> 10 | D25: =IFERROR(__xludf.DUMMYFUNCTION("""COMPUTED_VALUE"""),29.0) -> 29 | E25: =IFERROR(__xludf.DUMMYFUNCTION("""COMPUTED_VALUE"""),2010.0) -> 2010 | F25: =DATE(E25,C25,D25) -> 40480 | G25: 40433 | H25: =IFERROR(__xludf.DUMMYFUNCTION("split(G25,""/"")"),12.0) -> 12 | I25: =IFERROR(__xludf.DUMMYFUNCTION("""COMPUTED_VALUE"""),9.0) -> 9 | J25: =IFERROR(__xludf.DUMMYFUNCTION("""COMPUTED_VALUE"""),2010.0) -> 2010 | K25: =DATE(J25,H25,I25) -> 40521 | L25: L | M25: RUS | N25: 8293 | O25: Online | P25: 3325 | Q25: 437.2 | R25: 263.33 | S25: =Q25*P25 -> 1453690 | T25: =R25*P25 -> 875572.25 | U25: =S25-T25 -> 578117.75 | V25: =VLOOKUP(N25,products!A:B,2,0) -> Cosmetics | W25: Europe | X25: Eastern Europe | Y25: =U25/S25 -> 0.39768984 | Z25: =K25-F25 -> 41 | AA25: =WEEKDAY(F25,1) -> 6
A26: 114954173 | B26: 40239 | C26: =IFERROR(__xludf.DUMMYFUNCTION("split(B26,""/"")"),2.0) -> 2 | D26: =IFERROR(__xludf.DUMMYFUNCTION("""COMPUTED_VALUE"""),3.0) -> 3 | E26: =IFERROR(__xludf.DUMMYFUNCTION("""COMPUTED_VALUE"""),2010.0) -> 2010 | F26: =DATE(E26,C26,D26) -> 40212 | G26: 40484 | H26: =IFERROR(__xludf.DUMMYFUNCTION("split(G26,""/"")"),2.0) -> 2 | I26: =IFERROR(__xludf.DUMMYFUNCTION("""COMPUTED_VALUE"""),11.0) -> 11 | J26: =IFERROR(__xludf.DUMMYFUNCTION("""COMPUTED_VALUE"""),2010.0) -> 2010 | K26: =DATE(J26,H26,I26) -> 40220 | L26: C | M26: MLT | N26: 4594 | O26: Offline | P26: 6349 | Q26: 9.33 | R26: 6.92 | S26: =Q26*P26 -> 59236.17 | T26: =R26*P26 -> 43935.08 | U26: =S26-T26 -> 15301.09 | V26: =VLOOKUP(N26,products!A:B,2,0) -> Fruits | W26: Europe | X26: Southern Europe | Y26: =U26/S26 -> 0.25830654 | Z26: =K26-F26 -> 8 | AA26: =WEEKDAY(F26,1) -> 4
A27: 115363156 | B27: 42106 | C27: =IFERROR(__xludf.DUMMYFUNCTION("split(B27,""/"")"),12.0) -> 12 | D27: =IFERROR(__xludf.DUMMYFUNCTION("""COMPUTED_VALUE"""),4.0) -> 4 | E27: =IFERROR(__xludf.DUMMYFUNCTION("""COMPUTED_VALUE"""),2015.0) -> 2015 | F27: =DATE(E27,C27,D27) -> 42342 | G27: 42644 | H27: =IFERROR(__xludf.DUMMYFUNCTION("split(G27,""/"")"),1.0) -> 1 | I27: =IFERROR(__xludf.DUMMYFUNCTION("""COMPUTED_VALUE"""),10.0) -> 10 | J27: =IFERROR(__xludf.DUMMYFUNCTION("""COMPUTED_VALUE"""),2016.0) -> 2016 | K27: =DATE(J27,H27,I27) -> 42379 | L27: H | M27: UKR | N27: 8681 | O27: Offline | P27: 7376 | Q27: 651.21 | R27: 524.96 | S27: =Q27*P27 -> 4803325 | T27: =R27*P27 -> 3872105 | U27: =S27-T27 -> 931220 | V27: =VLOOKUP(N27,products!A:B,2,0) -> Office Supplies | W27: Europe | X27: Eastern Europe | Y27: =U27/S27 -> 0.19386987 | Z27: =K27-F27 -> 37 | AA27: =WEEKDAY(F27,1) -> 6
A28: 117929494 | B28: 1/24/2015 | C28: =IFERROR(__xludf.DUMMYFUNCTION("split(B28,""/"")"),1.0) -> 1 | D28: =IFERROR(__xludf.DUMMYFUNCTION("""COMPUTED_VALUE"""),24.0) -> 24 | E28: =IFERROR(__xludf.DUMMYFUNCTION("""COMPUTED_VALUE"""),2015.0) -> 2015 | F28: =DATE(E28,C28,D28) -> 42028 | G28: 42038 | H28: =IFERROR(__xludf.DUMMYFUNCTION("split(G28,""/"")"),3.0) -> 3 | I28: =IFERROR(__xludf.DUMMYFUNCTION("""COMPUTED_VALUE"""),2.0) -> 2 | J28: =IFERROR(__xludf.DUMMYFUNCTION("""COMPUTED_VALUE"""),2015.0) -> 2015 | K28: =DATE(J28,H28,I28) -> 42065 | L28: H | M28: Desconhecido | N28: 4594 | O28: Offline | P28: 6813 | Q28: 9.33 | R28: 6.92 | S28: =Q28*P28 -> 63565.29 | T28: =R28*P28 -> 47145.96 | U28: =S28-T28 -> 16419.33 | V28: =VLOOKUP(N28,products!A:B,2,0) -> Fruits | W28: Desconhecido | X28: Desconhecido | Y28: =U28/S28 -> 0.25830654 | Z28: =K28-F28 -> 37 | AA28: =WEEKDAY(F28,1) -> 7
A29: 118086564 | B29: 2/19/2016 | C29: =IFERROR(__xludf.DUMMYFUNCTION("split(B29,""/"")"),2.0) -> 2 | D29: =IFERROR(__xludf.DUMMYFUNCTION("""COMPUTED_VALUE"""),19.0) -> 19 | E29: =IFERROR(__xludf.DUMMYFUNCTION("""COMPUTED_VALUE"""),2016.0) -> 2016 | F29: =DATE(E29,C29,D29) -> 42419 | G29: 3/13/2016 | H29: =IFERROR(__xludf.DUMMYFUNCTION("split(G29,""/"")"),3.0) -> 3 | I29: =IFERROR(__xludf.DUMMYFUNCTION("""COMPUTED_VALUE"""),13.0) -> 13 | J29: =IFERROR(__xludf.DUMMYFUNCTION("""COMPUTED_VALUE"""),2016.0) -> 2016 | K29: =DATE(J29,H29,I29) -> 42442 | L29: M | M29: NOR | N29: 8969 | O29: Online | P29: 3293 | Q29: 152.58 | R29: 97.44 | S29: =Q29*P29 -> 502445.94 | T29: =R29*P29 -> 320869.92 | U29: =S29-T29 -> 181576.02 | V29: =VLOOKUP(N29,products!A:B,2,0) -> Snacks | W29: Europe | X29: Northern Europe | Y29: =U29/S29 -> 0.36138419 | Z29: =K29-F29 -> 23 | AA29: =WEEKDAY(F29,1) -> 6
A30: 118659913 | B30: 41678 | C30: =IFERROR(__xludf.DUMMYFUNCTION("split(B30,""/"")"),8.0) -> 8 | D30: =IFERROR(__xludf.DUMMYFUNCTION("""COMPUTED_VALUE"""),2.0) -> 2 | E30: =IFERROR(__xludf.DUMMYFUNCTION("""COMPUTED_VALUE"""),2014.0) -> 2014 | F30: =DATE(E30,C30,D30) -> 41853 | G30: 8/17/2014 | H30: =IFERROR(__xludf.DUMMYFUNCTION("split(G30,""/"")"),8.0) -> 8 | I30: =IFERROR(__xludf.DUMMYFUNCTION("""COMPUTED_VALUE"""),17.0) -> 17 | J30: =IFERROR(__xludf.DUMMYFUNCTION("""COMPUTED_VALUE"""),2014.0) -> 2014 | K30: =DATE(J30,H30,I30) -> 41868 | L30: C | M30: CZE | N30: 2103 | O30: Online | P30: 2960 | Q30: 205.7 | R30: 117.11 | S30: =Q30*P30 -> 608872 | T30: =R30*P30 -> 346645.6 | U30: =S30-T30 -> 262226.4 | V30: =VLOOKUP(N30,products!A:B,2,0) -> Cereal | W30: Europe | X30: Eastern Europe | Y30: =U30/S30 -> 0.43067574 | Z30: =K30-F30 -> 15 | AA30: =WEEKDAY(F30,1) -> 7
A31: 118859469 | B31: 40580 | C31: =IFERROR(__xludf.DUMMYFUNCTION("split(B31,""/"")"),6.0) -> 6 | D31: =IFERROR(__xludf.DUMMYFUNCTION("""COMPUTED_VALUE"""),2.0) -> 2 | E31: =IFERROR(__xludf.DUMMYFUNCTION("""COMPUTED_VALUE"""),2011.0) -> 2011 | F31: =DATE(E31,C31,D31) -> 40696 | G31: 40550 | H31: =IFERROR(__xludf.DUMMYFUNCTION("split(G31,""/"")"),7.0) -> 7 | I31: =IFERROR(__xludf.DUMMYFUNCTION("""COMPUTED_VALUE"""),1.0) -> 1 | J31: =IFERROR(__xludf.DUMMYFUNCTION("""COMPUTED_VALUE"""),2011.0) -> 2011 | K31: =DATE(J31,H31,I31) -> 40725 | L31: L | M31: Desconhecido | N31: 8969 | O31: Offline | P31: 2013 | Q31: 152.58 | R31: 97.44 | S31: =Q31*P31 -> 307143.54 | T31: =R31*P31 -> 196146.72 | U31: =S31-T31 -> 110996.82 | V31: =VLOOKUP(N31,products!A:B,2,0) -> Snacks | W31: Desconhecido | X31: Desconhecido | Y31: =U31/S31 -> 0.36138419 | Z31: =K31-F31 -> 29 | AA31: =WEEKDAY(F31,1) -> 5
A32: 119935786 | B32: 1/14/2015 | C32: =IFERROR(__xludf.DUMMYFUNCTION("split(B32,""/"")"),1.0) -> 1 | D32: =IFERROR(__xludf.DUMMYFUNCTION("""COMPUTED_VALUE"""),14.0) -> 14 | E32: =IFERROR(__xludf.DUMMYFUNCTION("""COMPUTED_VALUE"""),2015.0) -> 2015 | F32: =DATE(E32,C32,D32) -> 42018 | G32: 1/27/2015 | H32: =IFERROR(__xludf.DUMMYFUNCTION("split(G32,""/"")"),1.0) -> 1 | I32: =IFERROR(__xludf.DUMMYFUNCTION("""COMPUTED_VALUE"""),27.0) -> 27 | J32: =IFERROR(__xludf.DUMMYFUNCTION("""COMPUTED_VALUE"""),2015.0) -> 2015 | K32: =DATE(J32,H32,I32) -> 42031 | L32: L | M32: ROU | N32: 3127 | O32: Offline | P32: 519 | Q32: 81.73 | R32: 56.67 | S32: =Q32*P32 -> 42417.87 | T32: =R32*P32 -> 29411.73 | U32: =S32-T32 -> 13006.14 | V32: =VLOOKUP(N32,products!A:B,2,0) -> Personal Care | W32: Europe | X32: Eastern Europe | Y32: =U32/S32 -> 0.30661936 | Z32: =K32-F32 -> 13 | AA32: =WEEKDAY(F32,1) -> 4
A33: 120419871 | B33: 5/13/2015 | C33: =IFERROR(__xludf.DUMMYFUNCTION("split(B33,""/"")"),5.0) -> 5 | D33: =IFERROR(__xludf.DUMMYFUNCTION("""COMPUTED_VALUE"""),13.0) -> 13 | E33: =IFERROR(__xludf.DUMMYFUNCTION("""COMPUTED_VALUE"""),2015.0) -> 2015 | F33: =DATE(E33,C33,D33) -> 42137 | G33: 6/26/2015 | H33: =IFERROR(__xludf.DUMMYFUNCTION("split(G33,""/"")"),6.0) -> 6 | I33: =IFERROR(__xludf.DUMMYFUNCTION("""COMPUTED_VALUE"""),26.0) -> 26 | J33: =IFERROR(__xludf.DUMMYFUNCTION("""COMPUTED_VALUE"""),2015.0) -> 2015 | K33: =DATE(J33,H33,I33) -> 42181 | L33: H | M33: LTU | N33: 3127 | O33: Online | P33: 3771 | Q33: 81.73 | R33: 56.67 | S33: =Q33*P33 -> 308203.83 | T33: =R33*P33 -> 213702.57 | U33: =S33-T33 -> 94501.26 | V33: =VLOOKUP(N33,products!A:B,2,0) -> Personal Care | W33: Europe | X33: Northern Europe | Y33: =U33/S33 -> 0.30661936 | Z33: =K33-F33 -> 44 | AA33: =WEEKDAY(F33,1) -> 4
A34: 120977771 | B34: 3/23/2011 | C34: =IFERROR(__xludf.DUMMYFUNCTION("split(B34,""/"")"),3.0) -> 3 | D34: =IFERROR(__xludf.DUMMYFUNCTION("""COMPUTED_VALUE"""),23.0) -> 23 | E34: =IFERROR(__xludf.DUMMYFUNCTION("""COMPUTED_VALUE"""),2011.0) -> 2011 | F34: =DATE(E34,C34,D34) -> 40625 | G34: 40579 | H34: =IFERROR(__xludf.DUMMYFUNCTION("split(G34,""/"")"),5.0) -> 5 | I34: =IFERROR(__xludf.DUMMYFUNCTION("""COMPUTED_VALUE"""),2.0) -> 2 | J34: =IFERROR(__xludf.DUMMYFUNCTION("""COMPUTED_VALUE"""),2011.0) -> 2011 | K34: =DATE(J34,H34,I34) -> 40665 | L34: M | M34: ARM | N34: 4594 | O34: Online | P34: 8866 | Q34: 9.33 | R34: 6.92 | S34: =Q34*P34 -> 82719.78 | T34: =R34*P34 -> 61352.72 | U34: =S34-T34 -> 21367.06 | V34: =VLOOKUP(N34,products!A:B,2,0) -> Fruits | W34: Asia | X34: Western Asia | Y34: =U34/S34 -> 0.25830654 | Z34: =K34-F34 -> 40 | AA34: =WEEKDAY(F34,1) -> 4
A35: 121380746 | B35: 11/21/2016 | C35: =IFERROR(__xludf.DUMMYFUNCTION("split(B35,""/"")"),11.0) -> 11 | D35: =IFERROR(__xludf.DUMMYFUNCTION("""COMPUTED_VALUE"""),21.0) -> 21 | E35: =IFERROR(__xludf.DUMMYFUNCTION("""COMPUTED_VALUE"""),2016.0) -> 2016 | F35: =DATE(E35,C35,D35) -> 42695 | G35: 12/18/2016 | H35: =IFERROR(__xludf.DUMMYFUNCTION("split(G35,""/"")"),12.0) -> 12 | I35: =IFERROR(__xludf.DUMMYFUNCTION("""COMPUTED_VALUE"""),18.0) -> 18 | J35: =IFERROR(__xludf.DUMMYFUNCTION("""COMPUTED_VALUE"""),2016.0) -> 2016 | K35: =DATE(J35,H35,I35) -> 42722 | L35: C | M35: MLT | N35: 4594 | O35: Online | P35: 8115 | Q35: 9.33 | R35: 6.92 | S35: =Q35*P35 -> 75712.95 | T35: =R35*P35 -> 56155.8 | U35: =S35-T35 -> 19557.15 | V35: =VLOOKUP(N35,products!A:B,2,0) -> Fruits | W35: Europe | X35: Southern Europe | Y35: =U35/S35 -> 0.25830654 | Z35: =K35-F35 -> 27 | AA35: =WEEKDAY(F35,1) -> 2
A36: 121945512 | B36: 42951 | C36: =IFERROR(__xludf.DUMMYFUNCTION("split(B36,""/"")"),4.0) -> 4 | D36: =IFERROR(__xludf.DUMMYFUNCTION("""COMPUTED_VALUE"""),8.0) -> 8 | E36: =IFERROR(__xludf.DUMMYFUNCTION("""COMPUTED_VALUE"""),2017.0) -> 2017 | F36: =DATE(E36,C36,D36) -> 42833 | G36: 43073 | H36: =IFERROR(__xludf.DUMMYFUNCTION("split(G36,""/"")"),4.0) -> 4 | I36: =IFERROR(__xludf.DUMMYFUNCTION("""COMPUTED_VALUE"""),12.0) -> 12 | J36: =IFERROR(__xludf.DUMMYFUNCTION("""COMPUTED_VALUE"""),2017.0) -> 2017 | K36: =DATE(J36,H36,I36) -> 42837 | L36: C | M36: GBR | N36: 1270 | O36: Online | P36: 5242 | Q36: 47.45 | R36: 31.79 | S36: =Q36*P36 -> 248732.9 | T36: =R36*P36 -> 166643.18 | U36: =S36-T36 -> 82089.72 | V36: =VLOOKUP(N36,products!A:B,2,0) -> Beverages | W36: Europe | X36: Northern Europe | Y36: =U36/S36 -> 0.33003161 | Z36: =K36-F36 -> 4 | AA36: =WEEKDAY(F36,1) -> 7
A37: 122144210 | B37: 4/27/2017 | C37: =IFERROR(__xludf.DUMMYFUNCTION("split(B37,""/"")"),4.0) -> 4 | D37: =IFERROR(__xludf.DUMMYFUNCTION("""COMPUTED_VALUE"""),27.0) -> 27 | E37: =IFERROR(__xludf.DUMMYFUNCTION("""COMPUTED_VALUE"""),2017.0) -> 2017 | F37: =DATE(E37,C37,D37) -> 42852 | G37: 5/24/2017 | H37: =IFERROR(__xludf.DUMMYFUNCTION("split(G37,""/"")"),5.0) -> 5 | I37: =IFERROR(__xludf.DUMMYFUNCTION("""COMPUTED_VALUE"""),24.0) -> 24 | J37: =IFERROR(__xludf.DUMMYFUNCTION("""COMPUTED_VALUE"""),2017.0) -> 2017 | K37: =DATE(J37,H37,I37) -> 42879 | L37: C | M37: MNE | N37: 1270 | O37: Offline | P37: 4041 | Q37: 47.45 | R37: 31.79 | S37: =Q37*P37 -> 191745.45 | T37: =R37*P37 -> 128463.39 | U37: =S37-T37 -> 63282.06 | V37: =VLOOKUP(N37,products!A:B,2,0) -> Beverages | W37: Europe | X37: Southern Europe | Y37: =U37/S37 -> 0.33003161 | Z37: =K37-F37 -> 27 | AA37: =WEEKDAY(F37,1) -> 5
A38: 122372519 | B38: 42644 | C38: =IFERROR(__xludf.DUMMYFUNCTION("split(B38,""/"")"),1.0) -> 1 | D38: =IFERROR(__xludf.DUMMYFUNCTION("""COMPUTED_VALUE"""),10.0) -> 10 | E38: =IFERROR(__xludf.DUMMYFUNCTION("""COMPUTED_VALUE"""),2016.0) -> 2016 | F38: =DATE(E38,C38,D38) -> 42379 | G38: 1/13/2016 | H38: =IFERROR(__xludf.DUMMYFUNCTION("split(G38,""/"")"),1.0) -> 1 | I38: =IFERROR(__xludf.DUMMYFUNCTION("""COMPUTED_VALUE"""),13.0) -> 13 | J38: =IFERROR(__xludf.DUMMYFUNCTION("""COMPUTED_VALUE"""),2016.0) -> 2016 | K38: =DATE(J38,H38,I38) -> 42382 | L38: L | M38: PRT | N38: 1270 | O38: Offline | P38: 1603 | Q38: 47.45 | R38: 31.79 | S38: =Q38*P38 -> 76062.35 | T38: =R38*P38 -> 50959.37 | U38: =S38-T38 -> 25102.98 | V38: =VLOOKUP(N38,products!A:B,2,0) -> Beverages | W38: Europe | X38: Southern Europe | Y38: =U38/S38 -> 0.33003161 | Z38: =K38-F38 -> 3 | AA38: =WEEKDAY(F38,1) -> 1
A39: 122967326 | B39: 3/24/2017 | C39: =IFERROR(__xludf.DUMMYFUNCTION("split(B39,""/"")"),3.0) -> 3 | D39: =IFERROR(__xludf.DUMMYFUNCTION("""COMPUTED_VALUE"""),24.0) -> 24 | E39: =IFERROR(__xludf.DUMMYFUNCTION("""COMPUTED_VALUE"""),2017.0) -> 2017 | F39: =DATE(E39,C39,D39) -> 42818 | G39: 4/25/2017 | H39: =IFERROR(__xludf.DUMMYFUNCTION("split(G39,""/"")"),4.0) -> 4 | I39: =IFERROR(__xludf.DUMMYFUNCTION("""COMPUTED_VALUE"""),25.0) -> 25 | J39: =IFERROR(__xludf.DUMMYFUNCTION("""COMPUTED_VALUE"""),2017.0) -> 2017 | K39: =DATE(J39,H39,I39) -> 42850 | L39: H | M39: BLR | N39: 1270 | O39: Online | P39: 7619 | Q39: 47.45 | R39: 31.79 | S39: =Q39*P39 -> 361521.55 | T39: =R39*P39 -> 242208.01 | U39: =S39-T39 -> 119313.54 | V39: =VLOOKUP(N39,products!A:B,2,0) -> Beverages | W39: Europe | X39: Eastern Europe | Y39: =U39/S39 -> 0.33003161 | Z39: =K39-F39 -> 32 | AA39: =WEEKDAY(F39,1) -> 6
A40: 123086202 | B40: 41671 | C40: =IFERROR(__xludf.DUMMYFUNCTION("split(B40,""/"")"),1.0) -> 1 | D40: =IFERROR(__xludf.DUMMYFUNCTION("""COMPUTED_VALUE"""),2.0) -> 2 | E40: =IFERROR(__xludf.DUMMYFUNCTION("""COMPUTED_VALUE"""),2014.0) -> 2014 | F40: =DATE(E40,C40,D40) -> 41641 | G40: 2/20/2014 | H40: =IFERROR(__xludf.DUMMYFUNCTION("split(G40,""/"")"),2.0) -> 2 | I40: =IFERROR(__xludf.DUMMYFUNCTION("""COMPUTED_VALUE"""),20.0) -> 20 | J40: =IFERROR(__xludf.DUMMYFUNCTION("""COMPUTED_VALUE"""),2014.0) -> 2014 | K40: =DATE(J40,H40,I40) -> 41690 | L40: M | M40: EST | N40: 7331 | O40: Offline | P40: 2797 | Q40: 255.28 | R40: 159.42 | S40: =Q40*P40 -> 714018.16 | T40: =R40*P40 -> 445897.74 | U40: =S40-T40 -> 268120.42 | V40: =VLOOKUP(N40,products!A:B,2,0) -> Baby Food | W40: Europe | X40: Northern Europe | Y40: =U40/S40 -> 0.37550924 | Z40: =K40-F40 -> 49 | AA40: =WEEKDAY(F40,1) -> 5
...

Sheet PARETO
A1: Order ID | B1: Order Date | C1: mesOrder Date | D1: diaOrder Date | E1: anoOrder Date | F1: order date formatada | G1: Ship Date | H1: mesShip Date | I1: diaShip Date | J1: anoShip Date | K1: ship date formatada | L1: Order Priority | M1: Country Code | N1: Product ID | O1: Sales Channel | P1: Units Sold | Q1: Unit Price | R1: Unit Cost | S1: receita_total | T1: custo_total | U1: lucro_total | V1: item_type | W1: region | X1: sub-region | Y1: % margem | Z1: lead_time | AA1: dia da semana compra
A2: =IFERROR(__xludf.DUMMYFUNCTION("FILTER(events!A:AA, events!E:E = MAX(events!E:E))"),1.02230632E8) -> 102230632 | B2: =IFERROR(__xludf.DUMMYFUNCTION("""COMPUTED_VALUE"""),"5/13/2017") -> 5/13/2017 | C2: =IFERROR(__xludf.DUMMYFUNCTION("""COMPUTED_VALUE"""),5.0) -> 5 | D2: =IFERROR(__xludf.DUMMYFUNCTION("""COMPUTED_VALUE"""),13.0) -> 13 | E2: =IFERROR(__xludf.DUMMYFUNCTION("""COMPUTED_VALUE"""),2017.0) -> 2017 | F2: =IFERROR(__xludf.DUMMYFUNCTION("""COMPUTED_VALUE"""),42868.0) -> 42868 | G2: =IFERROR(__xludf.DUMMYFUNCTION("""COMPUTED_VALUE"""),"6/13/2017") -> 6/13/2017 | H2: =IFERROR(__xludf.DUMMYFUNCTION("""COMPUTED_VALUE"""),6.0) -> 6 | I2: =IFERROR(__xludf.DUMMYFUNCTION("""COMPUTED_VALUE"""),13.0) -> 13 | J2: =IFERROR(__xludf.DUMMYFUNCTION("""COMPUTED_VALUE"""),2017.0) -> 2017 | K2: =IFERROR(__xludf.DUMMYFUNCTION("""COMPUTED_VALUE"""),42899.0) -> 42899 | L2: =IFERROR(__xludf.DUMMYFUNCTION("""COMPUTED_VALUE"""),"L") -> L | M2: =IFERROR(__xludf.DUMMYFUNCTION("""COMPUTED_VALUE"""),"MNE") -> MNE | N2: =IFERROR(__xludf.DUMMYFUNCTION("""COMPUTED_VALUE"""),2455.0) -> 2455 | O2: =IFERROR(__xludf.DUMMYFUNCTION("""COMPUTED_VALUE"""),"Online") -> Online | P2: =IFERROR(__xludf.DUMMYFUNCTION("""COMPUTED_VALUE"""),1171.0) -> 1171 | Q2: =IFERROR(__xludf.DUMMYFUNCTION("""COMPUTED_VALUE"""),109.28) -> 109.28 | R2: =IFERROR(__xludf.DUMMYFUNCTION("""COMPUTED_VALUE"""),35.84) -> 35.84 | S2: =IFERROR(__xludf.DUMMYFUNCTION("""COMPUTED_VALUE"""),127966.88) -> 127966.88 | T2: =IFERROR(__xludf.DUMMYFUNCTION("""COMPUTED_VALUE"""),41968.64000000001) -> 41968.64 | U2: =IFERROR(__xludf.DUMMYFUNCTION("""COMPUTED_VALUE"""),85998.23999999999) -> 85998.24 | V2: =IFERROR(__xludf.DUMMYFUNCTION("""COMPUTED_VALUE"""),"Clothes") -> Clothes | W2: =IFERROR(__xludf.DUMMYFUNCTION("""COMPUTED_VALUE"""),"Europe") -> Europe | X2: =IFERROR(__xludf.DUMMYFUNCTION("""COMPUTED_VALUE"""),"Southern Europe") -> Southern Europe | Y2: =IFERROR(__xludf.DUMMYFUNCTION("""COMPUTED_VALUE"""),0.67203513909224) -> 0.67203514 | Z2: =IFERROR(__xludf.DUMMYFUNCTION("""COMPUTED_VALUE"""),31.0) -> 31 | AA2: =IFERROR(__xludf.DUMMYFUNCTION("""COMPUTED_VALUE"""),7.0) -> 7
A3: =IFERROR(__xludf.DUMMYFUNCTION("""COMPUTED_VALUE"""),1.04190576E8) -> 104190576 | B3: =IFERROR(__xludf.DUMMYFUNCTION("""COMPUTED_VALUE"""),"2/22/2017") -> 2/22/2017 | C3: =IFERROR(__xludf.DUMMYFUNCTION("""COMPUTED_VALUE"""),2.0) -> 2 | D3: =IFERROR(__xludf.DUMMYFUNCTION("""COMPUTED_VALUE"""),22.0) -> 22 | E3: =IFERROR(__xludf.DUMMYFUNCTION("""COMPUTED_VALUE"""),2017.0) -> 2017 | F3: =IFERROR(__xludf.DUMMYFUNCTION("""COMPUTED_VALUE"""),42788.0) -> 42788 | G3: =IFERROR(__xludf.DUMMYFUNCTION("""COMPUTED_VALUE"""),43072.0) -> 43072 | H3: =IFERROR(__xludf.DUMMYFUNCTION("""COMPUTED_VALUE"""),3.0) -> 3 | I3: =IFERROR(__xludf.DUMMYFUNCTION("""COMPUTED_VALUE"""),12.0) -> 12 | J3: =IFERROR(__xludf.DUMMYFUNCTION("""COMPUTED_VALUE"""),2017.0) -> 2017 | K3: =IFERROR(__xludf.DUMMYFUNCTION("""COMPUTED_VALUE"""),42806.0) -> 42806 | L3: =IFERROR(__xludf.DUMMYFUNCTION("""COMPUTED_VALUE"""),"C") -> C | M3: =IFERROR(__xludf.DUMMYFUNCTION("""COMPUTED_VALUE"""),"GEO") -> GEO | N3: =IFERROR(__xludf.DUMMYFUNCTION("""COMPUTED_VALUE"""),8875.0) -> 8875 | O3: =IFERROR(__xludf.DUMMYFUNCTION("""COMPUTED_VALUE"""),"Offline") -> Offline | P3: =IFERROR(__xludf.DUMMYFUNCTION("""COMPUTED_VALUE"""),1162.0) -> 1162 | Q3: =IFERROR(__xludf.DUMMYFUNCTION("""COMPUTED_VALUE"""),421.89) -> 421.89 | R3: =IFERROR(__xludf.DUMMYFUNCTION("""COMPUTED_VALUE"""),364.69) -> 364.69 | S3: =IFERROR(__xludf.DUMMYFUNCTION("""COMPUTED_VALUE"""),490236.18) -> 490236.18 | T3: =IFERROR(__xludf.DUMMYFUNCTION("""COMPUTED_VALUE"""),423769.77999999997) -> 423769.78 | U3: =IFERROR(__xludf.DUMMYFUNCTION("""COMPUTED_VALUE"""),66466.40000000002) -> 66466.4 | V3: =IFERROR(__xludf.DUMMYFUNCTION("""COMPUTED_VALUE"""),"Meat") -> Meat | W3: =IFERROR(__xludf.DUMMYFUNCTION("""COMPUTED_VALUE"""),"Asia") -> Asia | X3: =IFERROR(__xludf.DUMMYFUNCTION("""COMPUTED_VALUE"""),"Western Asia") -> Western Asia | Y3: =IFERROR(__xludf.DUMMYFUNCTION("""COMPUTED_VALUE"""),0.13558036455000125) -> 0.13558036 | Z3: =IFERROR(__xludf.DUMMYFUNCTION("""COMPUTED_VALUE"""),18.0) -> 18 | AA3: =IFERROR(__xludf.DUMMYFUNCTION("""COMPUTED_VALUE"""),4.0) -> 4
A4: =IFERROR(__xludf.DUMMYFUNCTION("""COMPUTED_VALUE"""),1.11246287E8) -> 111246287 | B4: =IFERROR(__xludf.DUMMYFUNCTION("""COMPUTED_VALUE"""),42984.0) -> 42984 | C4: =IFERROR(__xludf.DUMMYFUNCTION("""COMPUTED_VALUE"""),6.0) -> 6 | D4: =IFERROR(__xludf.DUMMYFUNCTION("""COMPUTED_VALUE"""),9.0) -> 9 | E4: =IFERROR(__xludf.DUMMYFUNCTION("""COMPUTED_VALUE"""),2017.0) -> 2017 | F4: =IFERROR(__xludf.DUMMYFUNCTION("""COMPUTED_VALUE"""),42895.0) -> 42895 | G4: =IFERROR(__xludf.DUMMYFUNCTION("""COMPUTED_VALUE"""),42773.0) -> 42773 | H4: =IFERROR(__xludf.DUMMYFUNCTION("""COMPUTED_VALUE"""),7.0) -> 7 | I4: =IFERROR(__xludf.DUMMYFUNCTION("""COMPUTED_VALUE"""),2.0) -> 2 | J4: =IFERROR(__xludf.DUMMYFUNCTION("""COMPUTED_VALUE"""),2017.0) -> 2017 | K4: =IFERROR(__xludf.DUMMYFUNCTION("""COMPUTED_VALUE"""),42918.0) -> 42918 | L4: =IFERROR(__xludf.DUMMYFUNCTION("""COMPUTED_VALUE"""),"M") -> M | M4: =IFERROR(__xludf.DUMMYFUNCTION("""COMPUTED_VALUE"""),"CYP") -> CYP | N4: =IFERROR(__xludf.DUMMYFUNCTION("""COMPUTED_VALUE"""),8875.0) -> 8875 | O4: =IFERROR(__xludf.DUMMYFUNCTION("""COMPUTED_VALUE"""),"Offline") -> Offline | P4: =IFERROR(__xludf.DUMMYFUNCTION("""COMPUTED_VALUE"""),9103.0) -> 9103 | Q4: =IFERROR(__xludf.DUMMYFUNCTION("""COMPUTED_VALUE"""),421.89) -> 421.89 | R4: =IFERROR(__xludf.DUMMYFUNCTION("""COMPUTED_VALUE"""),364.69) -> 364.69 | S4: =IFERROR(__xludf.DUMMYFUNCTION("""COMPUTED_VALUE"""),3840464.67) -> 3840464.7 | T4: =IFERROR(__xludf.DUMMYFUNCTION("""COMPUTED_VALUE"""),3319773.07) -> 3319773.1 | U4: =IFERROR(__xludf.DUMMYFUNCTION("""COMPUTED_VALUE"""),520691.6000000001) -> 520691.6 | V4: =IFERROR(__xludf.DUMMYFUNCTION("""COMPUTED_VALUE"""),"Meat") -> Meat | W4: =IFERROR(__xludf.DUMMYFUNCTION("""COMPUTED_VALUE"""),"Asia") -> Asia | X4: =IFERROR(__xludf.DUMMYFUNCTION("""COMPUTED_VALUE"""),"Western Asia") -> Western Asia | Y4: =IFERROR(__xludf.DUMMYFUNCTION("""COMPUTED_VALUE"""),0.13558036455000122) -> 0.13558036 | Z4: =IFERROR(__xludf.DUMMYFUNCTION("""COMPUTED_VALUE"""),23.0) -> 23 | AA4: =IFERROR(__xludf.DUMMYFUNCTION("""COMPUTED_VALUE"""),6.0) -> 6
A5: =IFERROR(__xludf.DUMMYFUNCTION("""COMPUTED_VALUE"""),1.21945512E8) -> 121945512 | B5: =IFERROR(__xludf.DUMMYFUNCTION("""COMPUTED_VALUE"""),42951.0) -> 42951 | C5: =IFERROR(__xludf.DUMMYFUNCTION("""COMPUTED_VALUE"""),4.0) -> 4 | D5: =IFERROR(__xludf.DUMMYFUNCTION("""COMPUTED_VALUE"""),8.0) -> 8 | E5: =IFERROR(__xludf.DUMMYFUNCTION("""COMPUTED_VALUE"""),2017.0) -> 2017 | F5: =IFERROR(__xludf.DUMMYFUNCTION("""COMPUTED_VALUE"""),42833.0) -> 42833 | G5: =IFERROR(__xludf.DUMMYFUNCTION("""COMPUTED_VALUE"""),43073.0) -> 43073 | H5: =IFERROR(__xludf.DUMMYFUNCTION("""COMPUTED_VALUE"""),4.0) -> 4 | I5: =IFERROR(__xludf.DUMMYFUNCTION("""COMPUTED_VALUE"""),12.0) -> 12 | J5: =IFERROR(__xludf.DUMMYFUNCTION("""COMPUTED_VALUE"""),2017.0) -> 2017 | K5: =IFERROR(__xludf.DUMMYFUNCTION("""COMPUTED_VALUE"""),42837.0) -> 42837 | L5: =IFERROR(__xludf.DUMMYFUNCTION("""COMPUTED_VALUE"""),"C") -> C | M5: =IFERROR(__xludf.DUMMYFUNCTION("""COMPUTED_VALUE"""),"GBR") -> GBR | N5: =IFERROR(__xludf.DUMMYFUNCTION("""COMPUTED_VALUE"""),1270.0) -> 1270 | O5: =IFERROR(__xludf.DUMMYFUNCTION("""COMPUTED_VALUE"""),"Online") -> Online | P5: =IFERROR(__xludf.DUMMYFUNCTION("""COMPUTED_VALUE"""),5242.0) -> 5242 | Q5: =IFERROR(__xludf.DUMMYFUNCTION("""COMPUTED_VALUE"""),47.45) -> 47.45 | R5: =IFERROR(__xludf.DUMMYFUNCTION("""COMPUTED_VALUE"""),31.79) -> 31.79 | S5: =IFERROR(__xludf.DUMMYFUNCTION("""COMPUTED_VALUE"""),248732.90000000002) -> 248732.9 | T5: =IFERROR(__xludf.DUMMYFUNCTION("""COMPUTED_VALUE"""),166643.18) -> 166643.18 | U5: =IFERROR(__xludf.DUMMYFUNCTION("""COMPUTED_VALUE"""),82089.72000000003) -> 82089.72 | V5: =IFERROR(__xludf.DUMMYFUNCTION("""COMPUTED_VALUE"""),"Beverages") -> Beverages | W5: =IFERROR(__xludf.DUMMYFUNCTION("""COMPUTED_VALUE"""),"Europe") -> Europe | X5: =IFERROR(__xludf.DUMMYFUNCTION("""COMPUTED_VALUE"""),"Northern Europe") -> Northern Europe | Y5: =IFERROR(__xludf.DUMMYFUNCTION("""COMPUTED_VALUE"""),0.3300316122233931) -> 0.33003161 | Z5: =IFERROR(__xludf.DUMMYFUNCTION("""COMPUTED_VALUE"""),4.0) -> 4 | AA5: =IFERROR(__xludf.DUMMYFUNCTION("""COMPUTED_VALUE"""),7.0) -> 7
A6: =IFERROR(__xludf.DUMMYFUNCTION("""COMPUTED_VALUE"""),1.2214421E8) -> 122144210 | B6: =IFERROR(__xludf.DUMMYFUNCTION("""COMPUTED_VALUE"""),"4/27/2017") -> 4/27/2017 | C6: =IFERROR(__xludf.DUMMYFUNCTION("""COMPUTED_VALUE"""),4.0) -> 4 | D6: =IFERROR(__xludf.DUMMYFUNCTION("""COMPUTED_VALUE"""),27.0) -> 27 | E6: =IFERROR(__xludf.DUMMYFUNCTION("""COMPUTED_VALUE"""),2017.0) -> 2017 | F6: =IFERROR(__xludf.DUMMYFUNCTION("""COMPUTED_VALUE"""),42852.0) -> 42852 | G6: =IFERROR(__xludf.DUMMYFUNCTION("""COMPUTED_VALUE"""),"5/24/2017") -> 5/24/2017 | H6: =IFERROR(__xludf.DUMMYFUNCTION("""COMPUTED_VALUE"""),5.0) -> 5 | I6: =IFERROR(__xludf.DUMMYFUNCTION("""COMPUTED_VALUE"""),24.0) -> 24 | J6: =IFERROR(__xludf.DUMMYFUNCTION("""COMPUTED_VALUE"""),2017.0) -> 2017 | K6: =IFERROR(__xludf.DUMMYFUNCTION("""COMPUTED_VALUE"""),42879.0) -> 42879 | L6: =IFERROR(__xludf.DUMMYFUNCTION("""COMPUTED_VALUE"""),"C") -> C | M6: =IFERROR(__xludf.DUMMYFUNCTION("""COMPUTED_VALUE"""),"MNE") -> MNE | N6: =IFERROR(__xludf.DUMMYFUNCTION("""COMPUTED_VALUE"""),1270.0) -> 1270 | O6: =IFERROR(__xludf.DUMMYFUNCTION("""COMPUTED_VALUE"""),"Offline") -> Offline | P6: =IFERROR(__xludf.DUMMYFUNCTION("""COMPUTED_VALUE"""),4041.0) -> 4041 | Q6: =IFERROR(__xludf.DUMMYFUNCTION("""COMPUTED_VALUE"""),47.45) -> 47.45 | R6: =IFERROR(__xludf.DUMMYFUNCTION("""COMPUTED_VALUE"""),31.79) -> 31.79 | S6: =IFERROR(__xludf.DUMMYFUNCTION("""COMPUTED_VALUE"""),191745.45) -> 191745.45 | T6: =IFERROR(__xludf.DUMMYFUNCTION("""COMPUTED_VALUE"""),128463.39) -> 128463.39 | U6: =IFERROR(__xludf.DUMMYFUNCTION("""COMPUTED_VALUE"""),63282.06000000001) -> 63282.06 | V6: =IFERROR(__xludf.DUMMYFUNCTION("""COMPUTED_VALUE"""),"Beverages") -> Beverages | W6: =IFERROR(__xludf.DUMMYFUNCTION("""COMPUTED_VALUE"""),"Europe") -> Europe | X6: =IFERROR(__xludf.DUMMYFUNCTION("""COMPUTED_VALUE"""),"Southern Europe") -> Southern Europe | Y6: =IFERROR(__xludf.DUMMYFUNCTION("""COMPUTED_VALUE"""),0.3300316122233931) -> 0.33003161 | Z6: =IFERROR(__xludf.DUMMYFUNCTION("""COMPUTED_VALUE"""),27.0) -> 27 | AA6: =IFERROR(__xludf.DUMMYFUNCTION("""COMPUTED_VALUE"""),5.0) -> 5
A7: =IFERROR(__xludf.DUMMYFUNCTION("""COMPUTED_VALUE"""),1.22967326E8) -> 122967326 | B7: =IFERROR(__xludf.DUMMYFUNCTION("""COMPUTED_VALUE"""),"3/24/2017") -> 3/24/2017 | C7: =IFERROR(__xludf.DUMMYFUNCTION("""COMPUTED_VALUE"""),3.0) -> 3 | D7: =IFERROR(__xludf.DUMMYFUNCTION("""COMPUTED_VALUE"""),24.0) -> 24 | E7: =IFERROR(__xludf.DUMMYFUNCTION("""COMPUTED_VALUE"""),2017.0) -> 2017 | F7: =IFERROR(__xludf.DUMMYFUNCTION("""COMPUTED_VALUE"""),42818.0) -> 42818 | G7: =IFERROR(__xludf.DUMMYFUNCTION("""COMPUTED_VALUE"""),"4/25/2017") -> 4/25/2017 | H7: =IFERROR(__xludf.DUMMYFUNCTION("""COMPUTED_VALUE"""),4.0) -> 4 | I7: =IFERROR(__xludf.DUMMYFUNCTION("""COMPUTED_VALUE"""),25.0) -> 25 | J7: =IFERROR(__xludf.DUMMYFUNCTION("""COMPUTED_VALUE"""),2017.0) -> 2017 | K7: =IFERROR(__xludf.DUMMYFUNCTION("""COMPUTED_VALUE"""),42850.0) -> 42850 | L7: =IFERROR(__xludf.DUMMYFUNCTION("""COMPUTED_VALUE"""),"H") -> H | M7: =IFERROR(__xludf.DUMMYFUNCTION("""COMPUTED_VALUE"""),"BLR") -> BLR | N7: =IFERROR(__xludf.DUMMYFUNCTION("""COMPUTED_VALUE"""),1270.0) -> 1270 | O7: =IFERROR(__xludf.DUMMYFUNCTION("""COMPUTED_VALUE"""),"Online") -> Online | P7: =IFERROR(__xludf.DUMMYFUNCTION("""COMPUTED_VALUE"""),7619.0) -> 7619 | Q7: =IFERROR(__xludf.DUMMYFUNCTION("""COMPUTED_VALUE"""),47.45) -> 47.45 | R7: =IFERROR(__xludf.DUMMYFUNCTION("""COMPUTED_VALUE"""),31.79) -> 31.79 | S7: =IFERROR(__xludf.DUMMYFUNCTION("""COMPUTED_VALUE"""),361521.55000000005) -> 361521.55 | T7: =IFERROR(__xludf.DUMMYFUNCTION("""COMPUTED_VALUE"""),242208.00999999998) -> 242208.01 | U7: =IFERROR(__xludf.DUMMYFUNCTION("""COMPUTED_VALUE"""),119313.54000000007) -> 119313.54 | V7: =IFERROR(__xludf.DUMMYFUNCTION("""COMPUTED_VALUE"""),"Beverages") -> Beverages | W7: =IFERROR(__xludf.DUMMYFUNCTION("""COMPUTED_VALUE"""),"Europe") -> Europe | X7: =IFERROR(__xludf.DUMMYFUNCTION("""COMPUTED_VALUE"""),"Eastern Europe") -> Eastern Europe | Y7: =IFERROR(__xludf.DUMMYFUNCTION("""COMPUTED_VALUE"""),0.33003161222339317) -> 0.33003161 | Z7: =IFERROR(__xludf.DUMMYFUNCTION("""COMPUTED_VALUE"""),32.0) -> 32 | AA7: =IFERROR(__xludf.DUMMYFUNCTION("""COMPUTED_VALUE"""),6.0) -> 6
A8: =IFERROR(__xludf.DUMMYFUNCTION("""COMPUTED_VALUE"""),1.25339686E8) -> 125339686 | B8: =IFERROR(__xludf.DUMMYFUNCTION("""COMPUTED_VALUE"""),43046.0) -> 43046 | C8: =IFERROR(__xludf.DUMMYFUNCTION("""COMPUTED_VALUE"""),7.0) -> 7 | D8: =IFERROR(__xludf.DUMMYFUNCTION("""COMPUTED_VALUE"""),11.0) -> 11 | E8: =IFERROR(__xludf.DUMMYFUNCTION("""COMPUTED_VALUE"""),2017.0) -> 2017 | F8: =IFERROR(__xludf.DUMMYFUNCTION("""COMPUTED_VALUE"""),42927.0) -> 42927 | G8: =IFERROR(__xludf.DUMMYFUNCTION("""COMPUTED_VALUE"""),"7/24/2017") -> 7/24/2017 | H8: =IFERROR(__xludf.DUMMYFUNCTION("""COMPUTED_VALUE"""),7.0) -> 7 | I8: =IFERROR(__xludf.DUMMYFUNCTION("""COMPUTED_VALUE"""),24.0) -> 24 | J8: =IFERROR(__xludf.DUMMYFUNCTION("""COMPUTED_VALUE"""),2017.0) -> 2017 | K8: =IFERROR(__xludf.DUMMYFUNCTION("""COMPUTED_VALUE"""),42940.0) -> 42940 | L8: =IFERROR(__xludf.DUMMYFUNCTION("""COMPUTED_VALUE"""),"L") -> L | M8: =IFERROR(__xludf.DUMMYFUNCTION("""COMPUTED_VALUE"""),"MKD") -> MKD | N8: =IFERROR(__xludf.DUMMYFUNCTION("""COMPUTED_VALUE"""),8969.0) -> 8969 | O8: =IFERROR(__xludf.DUMMYFUNCTION("""COMPUTED_VALUE"""),"Online") -> Online | P8: =IFERROR(__xludf.DUMMYFUNCTION("""COMPUTED_VALUE"""),9653.0) -> 9653 | Q8: =IFERROR(__xludf.DUMMYFUNCTION("""COMPUTED_VALUE"""),152.58) -> 152.58 | R8: =IFERROR(__xludf.DUMMYFUNCTION("""COMPUTED_VALUE"""),97.44) -> 97.44 | S8: =IFERROR(__xludf.DUMMYFUNCTION("""COMPUTED_VALUE"""),1472854.7400000002) -> 1472854.7 | T8: =IFERROR(__xludf.DUMMYFUNCTION("""COMPUTED_VALUE"""),940588.32) -> 940588.32 | U8: =IFERROR(__xludf.DUMMYFUNCTION("""COMPUTED_VALUE"""),532266.4200000003) -> 532266.42 | V8: =IFERROR(__xludf.DUMMYFUNCTION("""COMPUTED_VALUE"""),"Snacks") -> Snacks | W8: =IFERROR(__xludf.DUMMYFUNCTION("""COMPUTED_VALUE"""),"Europe") -> Europe | X8: =IFERROR(__xludf.DUMMYFUNCTION("""COMPUTED_VALUE"""),"Southern Europe") -> Southern Europe | Y8: =IFERROR(__xludf.DUMMYFUNCTION("""COMPUTED_VALUE"""),0.36138419189933163) -> 0.36138419 | Z8: =IFERROR(__xludf.DUMMYFUNCTION("""COMPUTED_VALUE"""),13.0) -> 13 | AA8: =IFERROR(__xludf.DUMMYFUNCTION("""COMPUTED_VALUE"""),3.0) -> 3
A9: =IFERROR(__xludf.DUMMYFUNCTION("""COMPUTED_VALUE"""),1.26948583E8) -> 126948583 | B9: =IFERROR(__xludf.DUMMYFUNCTION("""COMPUTED_VALUE"""),"5/24/2017") -> 5/24/2017 | C9: =IFERROR(__xludf.DUMMYFUNCTION("""COMPUTED_VALUE"""),5.0) -> 5 | D9: =IFERROR(__xludf.DUMMYFUNCTION("""COMPUTED_VALUE"""),24.0) -> 24 | E9: =IFERROR(__xludf.DUMMYFUNCTION("""COMPUTED_VALUE"""),2017.0) -> 2017 | F9: =IFERROR(__xludf.DUMMYFUNCTION("""COMPUTED_VALUE"""),42879.0) -> 42879 | G9: =IFERROR(__xludf.DUMMYFUNCTION("""COMPUTED_VALUE"""),42985.0) -> 42985 | H9: =IFERROR(__xludf.DUMMYFUNCTION("""COMPUTED_VALUE"""),7.0) -> 7 | I9: =IFERROR(__xludf.DUMMYFUNCTION("""COMPUTED_VALUE"""),9.0) -> 9 | J9: =IFERROR(__xludf.DUMMYFUNCTION("""COMPUTED_VALUE"""),2017.0) -> 2017 | K9: =IFERROR(__xludf.DUMMYFUNCTION("""COMPUTED_VALUE"""),42925.0) -> 42925 | L9: =IFERROR(__xludf.DUMMYFUNCTION("""COMPUTED_VALUE"""),"C") -> C | M9: =IFERROR(__xludf.DUMMYFUNCTION("""COMPUTED_VALUE"""),"Desconhecido") -> Desconhecido | N9: =IFERROR(__xludf.DUMMYFUNCTION("""COMPUTED_VALUE"""),7331.0) -> 7331 | O9: =IFERROR(__xludf.DUMMYFUNCTION("""COMPUTED_VALUE"""),"Online") -> Online | P9: =IFERROR(__xludf.DUMMYFUNCTION("""COMPUTED_VALUE"""),5762.0) -> 5762 | Q9: =IFERROR(__xludf.DUMMYFUNCTION("""COMPUTED_VALUE"""),255.28) -> 255.28 | R9: =IFERROR(__xludf.DUMMYFUNCTION("""COMPUTED_VALUE"""),159.42) -> 159.42 | S9: =IFERROR(__xludf.DUMMYFUNCTION("""COMPUTED_VALUE"""),1470923.36) -> 1470923.4 | T9: =IFERROR(__xludf.DUMMYFUNCTION("""COMPUTED_VALUE"""),918578.0399999999) -> 918578.04 | U9: =IFERROR(__xludf.DUMMYFUNCTION("""COMPUTED_VALUE"""),552345.3200000002) -> 552345.32 | V9: =IFERROR(__xludf.DUMMYFUNCTION("""COMPUTED_VALUE"""),"Baby Food") -> Baby Food | W9: =IFERROR(__xludf.DUMMYFUNCTION("""COMPUTED_VALUE"""),"Desconhecido") -> Desconhecido | X9: =IFERROR(__xludf.DUMMYFUNCTION("""COMPUTED_VALUE"""),"Desconhecido") -> Desconhecido | Y9: =IFERROR(__xludf.DUMMYFUNCTION("""COMPUTED_VALUE"""),0.3755092447508619) -> 0.37550924 | Z9: =IFERROR(__xludf.DUMMYFUNCTION("""COMPUTED_VALUE"""),46.0) -> 46 | AA9: =IFERROR(__xludf.DUMMYFUNCTION("""COMPUTED_VALUE"""),4.0) -> 4
A10: =IFERROR(__xludf.DUMMYFUNCTION("""COMPUTED_VALUE"""),1.31585586E8) -> 131585586 | B10: =IFERROR(__xludf.DUMMYFUNCTION("""COMPUTED_VALUE"""),"3/13/2017") -> 3/13/2017 | C10: =IFERROR(__xludf.DUMMYFUNCTION("""COMPUTED_VALUE"""),3.0) -> 3 | D10: =IFERROR(__xludf.DUMMYFUNCTION("""COMPUTED_VALUE"""),13.0) -> 13 | E10: =IFERROR(__xludf.DUMMYFUNCTION("""COMPUTED_VALUE"""),2017.0) -> 2017 | F10: =IFERROR(__xludf.DUMMYFUNCTION("""COMPUTED_VALUE"""),42807.0) -> 42807 | G10: =IFERROR(__xludf.DUMMYFUNCTION("""COMPUTED_VALUE"""),"4/13/2017") -> 4/13/2017 | H10: =IFERROR(__xludf.DUMMYFUNCTION("""COMPUTED_VALUE"""),4.0) -> 4 | I10: =IFERROR(__xludf.DUMMYFUNCTION("""COMPUTED_VALUE"""),13.0) -> 13 | J10: =IFERROR(__xludf.DUMMYFUNCTION("""COMPUTED_VALUE"""),2017.0) -> 2017 | K10: =IFERROR(__xludf.DUMMYFUNCTION("""COMPUTED_VALUE"""),42838.0) -> 42838 | L10: =IFERROR(__xludf.DUMMYFUNCTION("""COMPUTED_VALUE"""),"C") -> C | M10: =IFERROR(__xludf.DUMMYFUNCTION("""COMPUTED_VALUE"""),"FRA") -> FRA | N10: =IFERROR(__xludf.DUMMYFUNCTION("""COMPUTED_VALUE"""),3127.0) -> 3127 | O10: =IFERROR(__xludf.DUMMYFUNCTION("""COMPUTED_VALUE"""),"Offline") -> Offline | P10: =IFERROR(__xludf.DUMMYFUNCTION("""COMPUTED_VALUE"""),7954.0) -> 7954 | Q10: =IFERROR(__xludf.DUMMYFUNCTION("""COMPUTED_VALUE"""),81.73) -> 81.73 | R10: =IFERROR(__xludf.DUMMYFUNCTION("""COMPUTED_VALUE"""),56.67) -> 56.67 | S10: =IFERROR(__xludf.DUMMYFUNCTION("""COMPUTED_VALUE"""),650080.42) -> 650080.42 | T10: =IFERROR(__xludf.DUMMYFUNCTION("""COMPUTED_VALUE"""),450753.18) -> 450753.18 | U10: =IFERROR(__xludf.DUMMYFUNCTION("""COMPUTED_VALUE"""),199327.24000000005) -> 199327.24 | V10: =IFERROR(__xludf.DUMMYFUNCTION("""COMPUTED_VALUE"""),"Personal Care") -> Personal Care | W10: =IFERROR(__xludf.DUMMYFUNCTION("""COMPUTED_VALUE"""),"Europe") -> Europe | X10: =IFERROR(__xludf.DUMMYFUNCTION("""COMPUTED_VALUE"""),"Western Europe") -> Western Europe | Y10: =IFERROR(__xludf.DUMMYFUNCTION("""COMPUTED_VALUE"""),0.30661935641747223) -> 0.30661936 | Z10: =IFERROR(__xludf.DUMMYFUNCTION("""COMPUTED_VALUE"""),31.0) -> 31 | AA10: =IFERROR(__xludf.DUMMYFUNCTION("""COMPUTED_VALUE"""),2.0) -> 2
A11: =IFERROR(__xludf.DUMMYFUNCTION("""COMPUTED_VALUE"""),1.32069671E8) -> 132069671 | B11: =IFERROR(__xludf.DUMMYFUNCTION("""COMPUTED_VALUE"""),42985.0) -> 42985 | C11: =IFERROR(__xludf.DUMMYFUNCTION("""COMPUTED_VALUE"""),7.0) -> 7 | D11: =IFERROR(__xludf.DUMMYFUNCTION("""COMPUTED_VALUE"""),9.0) -> 9 | E11: =IFERROR(__xludf.DUMMYFUNCTION("""COMPUTED_VALUE"""),2017.0) -> 2017 | F11: =IFERROR(__xludf.DUMMYFUNCTION("""COMPUTED_VALUE"""),42925.0) -> 42925 | G11: =IFERROR(__xludf.DUMMYFUNCTION("""COMPUTED_VALUE"""),"7/20/2017") -> 7/20/2017 | H11: =IFERROR(__xludf.DUMMYFUNCTION("""COMPUTED_VALUE"""),7.0) -> 7 | I11: =IFERROR(__xludf.DUMMYFUNCTION("""COMPUTED_VALUE"""),20.0) -> 20 | J11: =IFERROR(__xludf.DUMMYFUNCTION("""COMPUTED_VALUE"""),2017.0) -> 2017 | K11: =IFERROR(__xludf.DUMMYFUNCTION("""COMPUTED_VALUE"""),42936.0) -> 42936 | L11: =IFERROR(__xludf.DUMMYFUNCTION("""COMPUTED_VALUE"""),"M") -> M | M11: =IFERROR(__xludf.DUMMYFUNCTION("""COMPUTED_VALUE"""),"AUT") -> AUT | N11: =IFERROR(__xludf.DUMMYFUNCTION("""COMPUTED_VALUE"""),3127.0) -> 3127 | O11: =IFERROR(__xludf.DUMMYFUNCTION("""COMPUTED_VALUE"""),"Online") -> Online | P11: =IFERROR(__xludf.DUMMYFUNCTION("""COMPUTED_VALUE"""),1205.0) -> 1205 | Q11: =IFERROR(__xludf.DUMMYFUNCTION("""COMPUTED_VALUE"""),81.73) -> 81.73 | R11: =IFERROR(__xludf.DUMMYFUNCTION("""COMPUTED_VALUE"""),56.67) -> 56.67 | S11: =IFERROR(__xludf.DUMMYFUNCTION("""COMPUTED_VALUE"""),98484.65000000001) -> 98484.65 | T11: =IFERROR(__xludf.DUMMYFUNCTION("""COMPUTED_VALUE"""),68287.35) -> 68287.35 | U11: =IFERROR(__xludf.DUMMYFUNCTION("""COMPUTED_VALUE"""),30197.300000000003) -> 30197.3 | V11: =IFERROR(__xludf.DUMMYFUNCTION("""COMPUTED_VALUE"""),"Personal Care") -> Personal Care | W11: =IFERROR(__xludf.DUMMYFUNCTION("""COMPUTED_VALUE"""),"Europe") -> Europe | X11: =IFERROR(__xludf.DUMMYFUNCTION("""COMPUTED_VALUE"""),"Western Europe") -> Western Europe | Y11: =IFERROR(__xludf.DUMMYFUNCTION("""COMPUTED_VALUE"""),0.3066193564174722) -> 0.30661936 | Z11: =IFERROR(__xludf.DUMMYFUNCTION("""COMPUTED_VALUE"""),11.0) -> 11 | AA11: =IFERROR(__xludf.DUMMYFUNCTION("""COMPUTED_VALUE"""),1.0) -> 1
